[2019-05-25 20:45:22,308] ERROR in app: Exception on /log [GET]
Traceback (most recent call last):
  File "/home/leonardo/Documents/Projects/employees-CRUD/api/envapi/lib/python3.6/site-packages/flask/app.py", line 2292, in wsgi_app
    response = self.full_dispatch_request()
  File "/home/leonardo/Documents/Projects/employees-CRUD/api/envapi/lib/python3.6/site-packages/flask/app.py", line 1815, in full_dispatch_request
    rv = self.handle_user_exception(e)
  File "/home/leonardo/Documents/Projects/employees-CRUD/api/envapi/lib/python3.6/site-packages/flask_cors/extension.py", line 161, in wrapped_function
    return cors_after_request(app.make_response(f(*args, **kwargs)))
  File "/home/leonardo/Documents/Projects/employees-CRUD/api/envapi/lib/python3.6/site-packages/flask/app.py", line 1718, in handle_user_exception
    reraise(exc_type, exc_value, tb)
  File "/home/leonardo/Documents/Projects/employees-CRUD/api/envapi/lib/python3.6/site-packages/flask/_compat.py", line 35, in reraise
    raise value
  File "/home/leonardo/Documents/Projects/employees-CRUD/api/envapi/lib/python3.6/site-packages/flask/app.py", line 1813, in full_dispatch_request
    rv = self.dispatch_request()
  File "/home/leonardo/Documents/Projects/employees-CRUD/api/envapi/lib/python3.6/site-packages/flask/app.py", line 1799, in dispatch_request
    return self.view_functions[rule.endpoint](**req.view_args)
  File "/home/leonardo/Documents/Projects/employees-CRUD/api/simple_auth/authorization.py", line 18, in decorated
    auth = request.Authorization
  File "/home/leonardo/Documents/Projects/employees-CRUD/api/envapi/lib/python3.6/site-packages/werkzeug/local.py", line 348, in __getattr__
    return getattr(self._get_current_object(), name)
AttributeError: 'Request' object has no attribute 'Authorization'
[2019-05-25 20:45:38,359] ERROR in app: Exception on /log [GET]
Traceback (most recent call last):
  File "/home/leonardo/Documents/Projects/employees-CRUD/api/envapi/lib/python3.6/site-packages/flask/app.py", line 2292, in wsgi_app
    response = self.full_dispatch_request()
  File "/home/leonardo/Documents/Projects/employees-CRUD/api/envapi/lib/python3.6/site-packages/flask/app.py", line 1815, in full_dispatch_request
    rv = self.handle_user_exception(e)
  File "/home/leonardo/Documents/Projects/employees-CRUD/api/envapi/lib/python3.6/site-packages/flask_cors/extension.py", line 161, in wrapped_function
    return cors_after_request(app.make_response(f(*args, **kwargs)))
  File "/home/leonardo/Documents/Projects/employees-CRUD/api/envapi/lib/python3.6/site-packages/flask/app.py", line 1718, in handle_user_exception
    reraise(exc_type, exc_value, tb)
  File "/home/leonardo/Documents/Projects/employees-CRUD/api/envapi/lib/python3.6/site-packages/flask/_compat.py", line 35, in reraise
    raise value
  File "/home/leonardo/Documents/Projects/employees-CRUD/api/envapi/lib/python3.6/site-packages/flask/app.py", line 1813, in full_dispatch_request
    rv = self.dispatch_request()
  File "/home/leonardo/Documents/Projects/employees-CRUD/api/envapi/lib/python3.6/site-packages/flask/app.py", line 1799, in dispatch_request
    return self.view_functions[rule.endpoint](**req.view_args)
  File "/home/leonardo/Documents/Projects/employees-CRUD/api/simple_auth/authorization.py", line 18, in decorated
    auth = request.authorization
  File "/home/leonardo/Documents/Projects/employees-CRUD/api/envapi/lib/python3.6/site-packages/werkzeug/local.py", line 348, in __getattr__
    return getattr(self._get_current_object(), name)
AttributeError: 'Request' object has no attribute 'Authorization'
[2019-05-25 21:09:48,382] INFO in api: Employees retrieved.
[2019-05-25 21:10:22,547] INFO in api: Employees retrieved.
[2019-05-25 21:17:40,858] ERROR in api: ERROR: 404 Not Found: The requested URL was not found on the server. If you entered the URL manually please check your spelling and try again.
[2019-05-25 21:18:01,817] INFO in api: Employees retrieved.
[2019-05-25 21:19:00,622] ERROR in api: ERROR: 404 Not Found: The requested URL was not found on the server. If you entered the URL manually please check your spelling and try again.
[2019-05-25 21:19:21,770] ERROR in api: ERROR: 404 Not Found: The requested URL was not found on the server. If you entered the URL manually please check your spelling and try again.
[2019-05-25 21:20:37,538] ERROR in api: ERROR: 404 Not Found: The requested URL was not found on the server. If you entered the URL manually please check your spelling and try again.
[2019-05-25 21:21:05,744] ERROR in api: ERROR: 404 Not Found: The requested URL was not found on the server. If you entered the URL manually please check your spelling and try again.
[2019-05-25 21:22:03,542] ERROR in api: ERROR: 404 Not Found: The requested URL was not found on the server. If you entered the URL manually please check your spelling and try again.
[2019-05-25 21:22:04,486] ERROR in api: ERROR: 404 Not Found: The requested URL was not found on the server. If you entered the URL manually please check your spelling and try again.
[2019-05-25 21:22:17,170] INFO in api: Employees retrieved.
[2019-05-25 21:22:45,503] INFO in api: Employees retrieved.
[2019-05-25 21:22:53,617] ERROR in api: ERROR: 404 Not Found: The requested URL was not found on the server. If you entered the URL manually please check your spelling and try again.
[2019-05-25 21:24:22,232] INFO in api: Employees retrieved.
[2019-05-25 21:24:40,314] INFO in api: Employees retrieved.
[2019-05-25 21:24:40,314] ERROR in app: Exception on /employee [GET]
Traceback (most recent call last):
  File "/home/leonardo/Documents/Projects/employees-CRUD/api/envapi/lib/python3.6/site-packages/flask/app.py", line 2292, in wsgi_app
    response = self.full_dispatch_request()
  File "/home/leonardo/Documents/Projects/employees-CRUD/api/envapi/lib/python3.6/site-packages/flask/app.py", line 1815, in full_dispatch_request
    rv = self.handle_user_exception(e)
  File "/home/leonardo/Documents/Projects/employees-CRUD/api/envapi/lib/python3.6/site-packages/flask_cors/extension.py", line 161, in wrapped_function
    return cors_after_request(app.make_response(f(*args, **kwargs)))
  File "/home/leonardo/Documents/Projects/employees-CRUD/api/envapi/lib/python3.6/site-packages/flask/app.py", line 1718, in handle_user_exception
    reraise(exc_type, exc_value, tb)
  File "/home/leonardo/Documents/Projects/employees-CRUD/api/envapi/lib/python3.6/site-packages/flask/_compat.py", line 35, in reraise
    raise value
  File "/home/leonardo/Documents/Projects/employees-CRUD/api/envapi/lib/python3.6/site-packages/flask/app.py", line 1813, in full_dispatch_request
    rv = self.dispatch_request()
  File "/home/leonardo/Documents/Projects/employees-CRUD/api/envapi/lib/python3.6/site-packages/flask/app.py", line 1799, in dispatch_request
    return self.view_functions[rule.endpoint](**req.view_args)
  File "api.py", line 99, in get_employee
    return json.dumps([pessoa.serialize for pessoa in pessoas.paginate(page,size).items]), 200, {'Content-Type': 'application/json'}
  File "/home/leonardo/Documents/Projects/employees-CRUD/api/envapi/lib/python3.6/site-packages/flask_sqlalchemy/__init__.py", line 484, in paginate
    if page < 1:
TypeError: '<' not supported between instances of 'str' and 'int'
[2019-05-25 21:25:26,441] INFO in api: Employees retrieved.
[2019-05-25 21:25:26,441] ERROR in app: Exception on /employee [GET]
Traceback (most recent call last):
  File "/home/leonardo/Documents/Projects/employees-CRUD/api/envapi/lib/python3.6/site-packages/flask/app.py", line 2292, in wsgi_app
    response = self.full_dispatch_request()
  File "/home/leonardo/Documents/Projects/employees-CRUD/api/envapi/lib/python3.6/site-packages/flask/app.py", line 1815, in full_dispatch_request
    rv = self.handle_user_exception(e)
  File "/home/leonardo/Documents/Projects/employees-CRUD/api/envapi/lib/python3.6/site-packages/flask_cors/extension.py", line 161, in wrapped_function
    return cors_after_request(app.make_response(f(*args, **kwargs)))
  File "/home/leonardo/Documents/Projects/employees-CRUD/api/envapi/lib/python3.6/site-packages/flask/app.py", line 1718, in handle_user_exception
    reraise(exc_type, exc_value, tb)
  File "/home/leonardo/Documents/Projects/employees-CRUD/api/envapi/lib/python3.6/site-packages/flask/_compat.py", line 35, in reraise
    raise value
  File "/home/leonardo/Documents/Projects/employees-CRUD/api/envapi/lib/python3.6/site-packages/flask/app.py", line 1813, in full_dispatch_request
    rv = self.dispatch_request()
  File "/home/leonardo/Documents/Projects/employees-CRUD/api/envapi/lib/python3.6/site-packages/flask/app.py", line 1799, in dispatch_request
    return self.view_functions[rule.endpoint](**req.view_args)
  File "api.py", line 100, in get_employee
    return json.dumps([pessoa.serialize for pessoa in pessoas.paginate(page,size).items]), 200, {'Content-Type': 'application/json'}
  File "/home/leonardo/Documents/Projects/employees-CRUD/api/envapi/lib/python3.6/site-packages/flask_sqlalchemy/__init__.py", line 484, in paginate
    if page < 1:
TypeError: '<' not supported between instances of 'str' and 'int'
[2019-05-25 21:25:57,384] INFO in api: Employees retrieved.
